Workbook
Name _xlchart.v1.3: '1_TOTAL'!$I$2:$I$23
Name _xlchart.v1.4: '1_TOTAL'!$J$1
Name _xlchart.v1.1: '1_TOTAL'!$J$1
Name _xlchart.v1.9: '2_SECTOR WISE'!$I$2:$I$23
Name _xlchart.v1.0: '1_TOTAL'!$I$2:$I$23
Name _xlchart.v1.12: '2_SECTOR WISE'!$F$2:$F$81
Name _xlchart.v1.2: '1_TOTAL'!$J$2:$J$23
Name _xlchart.v1.7: '1_TOTAL'!$G$1
Name _xlchart.v1.13: '2_SECTOR WISE'!$G$1
Name _xlchart.v1.6: '1_TOTAL'!$F$2:$F$81
Name _xlchart.v1.11: '2_SECTOR WISE'!$J$2:$J$23
Name _xlchart.v1.5: '1_TOTAL'!$J$2:$J$23
Name _xlchart.v1.8: '1_TOTAL'!$G$2:$G$81
Name _xlchart.v1.10: '2_SECTOR WISE'!$J$1
Name _xlchart.v1.14: '2_SECTOR WISE'!$G$2:$G$81

Sheet 1_TOTAL
A1: Sr.No | B1: Name of Script | C1: Stock Price | D1: Quantity | E1: Total | F1: SECTOR | G1: Total % | I1: Sector | J1: Sector % | K1: Total
A2: 23 | B2: UPL | C2: 505 | D2: 70 | E2: =D2*C2 -> 35350 | F2: AGRI | G2: ='1_TOTAL'!$E2*100/'1_TOTAL'!$E$82 -> 1.2135062 | I2: AGRI | J2: =SUM(G2:G3) -> 1.7689385 | K2: =SUM(E2:E3) -> 51530
A3: 52 | B3: GODJREJ AGROVET | C3: 809 | D3: 20 | E3: ='1_TOTAL'!$C3*'1_TOTAL'!$D3 -> 16180 | F3: AGRI | G3: ='1_TOTAL'!$E3*100/'1_TOTAL'!$E$82 -> 0.55543227 | I3: Auto Ancillaries | J3: =SUM(G4:G9) -> 4.7355922 | K3: =SUM(E4:E9) -> 137950
A4: 29 | B4: Pricol | C4: 524 | D4: 20 | E4: ='1_TOTAL'!$C4*'1_TOTAL'!$D4 -> 10480 | F4: AUTO ANCILLLARY | G4: ='1_TOTAL'!$E4*100/'1_TOTAL'!$E$82 -> 0.35976083 | I4: Aviation | J4: =G10 -> 0.78302905 | K4: =E10 -> 22810
A5: 38 | B5: SANSERA | C5: 1033 | D5: 20 | E5: ='1_TOTAL'!$C5*'1_TOTAL'!$D5 -> 20660 | F5: AUTO ANCILLLARY | G5: ='1_TOTAL'!$E5*100/'1_TOTAL'!$E$82 -> 0.70922315 | I5: Banking | J5: =SUM(G11:G17) -> 14.920188 | K5: =SUM(E11:E17) -> 434632
A6: 44 | B6: SUPRAJIT | C6: 400 | D6: 100 | E6: ='1_TOTAL'!$C6*'1_TOTAL'!$D6 -> 40000 | F6: AUTO ANCILLLARY | G6: ='1_TOTAL'!$E6*100/'1_TOTAL'!$E$82 -> 1.3731329 | I6: Chemical | J6: =SUM(G18:G23) -> 7.8578218 | K6: =SUM(E18:E23) -> 228902
A7: 51 | B7: PCBL | C7: 748 | D7: 55 | E7: ='1_TOTAL'!$C7*'1_TOTAL'!$D7 -> 41140 | F7: AUTO ANCILLLARY | G7: ='1_TOTAL'!$E7*100/'1_TOTAL'!$E$82 -> 1.4122672 | I7: CLEAN ENERGY | J7: =G24 -> 0.56023823 | K7: =E24 -> 16320
A8: 53 | B8: VARROC | C8: 25 | D8: 548 | E8: ='1_TOTAL'!$C8*'1_TOTAL'!$D8 -> 13700 | F8: AUTO ANCILLLARY | G8: ='1_TOTAL'!$E8*100/'1_TOTAL'!$E$82 -> 0.47029803 | I8: CONSTRUCTION | J8: =SUM(G25:G27) -> 3.120321 | K8: =SUM(E25:E27) -> 90896.4
A9: 77 | B9: SHANTI GEARS | C9: 570 | D9: 21 | E9: ='1_TOTAL'!$C9*'1_TOTAL'!$D9 -> 11970 | F9: AUTO ANCILLLARY | G9: ='1_TOTAL'!$E9*100/'1_TOTAL'!$E$82 -> 0.41091003 | I9: DEFENCE | J9: =G28 -> 1.1905062 | K9: =E28 -> 34680
A10: 78 | B10: INDIGO | C10: 4562 | D10: 5 | E10: ='1_TOTAL'!$C10*'1_TOTAL'!$D10 -> 22810 | F10: AVIATION | G10: ='1_TOTAL'!$E10*100/'1_TOTAL'!$E$82 -> 0.78302905 | I10: ELECTRONICS | J10: =SUM(G29:G31) -> 1.9834219 | K10: =SUM(E29:E31) -> 57778
A11: 8 | B11: HDFC Bank | C11: 1518.9 | D11: 100 | E11: =D11*C11 -> 151890 | F11: BANKING | G11: ='1_TOTAL'!$E11*100/'1_TOTAL'!$E$82 -> 5.214129 | I11: FASHION | J11: =G32 -> 0.78186189 | K11: =E32 -> 22776
A12: 11 | B12: IDFC First bank | C12: 81.17 | D12: 700 | E12: =D12*C12 -> 56819 | F12: BANKING | G12: ='1_TOTAL'!$E12*100/'1_TOTAL'!$E$82 -> 1.950501 | I12: FINANCE | J12: =SUM(G33:G41) -> 9.3289933 | K12: =SUM(E33:E41) -> 271757.91
A13: 15 | B13: Kotak Bank | C13: 1752 | D13: 71 | E13: =D13*C13 -> 124392 | F13: BANKING | G13: ='1_TOTAL'!$E13*100/'1_TOTAL'!$E$82 -> 4.2701688 | I13: FMCG | J13: =SUM(G42:G44) -> 10.041807 | K13: =SUM(E42:E44) -> 292522.5
A14: 55 | B14: RBL BANK | C14: 230 | D14: 100 | E14: ='1_TOTAL'!$C14*'1_TOTAL'!$D14 -> 23000 | F14: BANKING | G14: ='1_TOTAL'!$E14*100/'1_TOTAL'!$E$82 -> 0.78955143 | I14: INSURANCE | J14: =SUM(G45:G46) -> 3.0823745 | K14: =SUM(E45:E46) -> 89791
A15: 64 | B15: CITY BANK | C15: 137 | D15: 30 | E15: ='1_TOTAL'!$C15*'1_TOTAL'!$D15 -> 4110 | F15: BANKING | G15: ='1_TOTAL'!$E15*100/'1_TOTAL'!$E$82 -> 0.14108941 | I15: IT | J15: =SUM(G47:G60) -> 17.91947 | K15: =SUM(E47:E60) -> 522002.5
A16: 66 | B16: AXIS BANK | C16: 1175 | D16: 27 | E16: ='1_TOTAL'!$C16*'1_TOTAL'!$D16 -> 31725 | F16: BANKING | G16: ='1_TOTAL'!$E16*100/'1_TOTAL'!$E$82 -> 1.089066 | I16: LOGISTICS | J16: =SUM(G61:G62) -> 1.975595 | K16: =SUM(E61:E62) -> 57550
A17: 67 | B17: ICICI BANK | C17: 1186 | D17: 36 | E17: ='1_TOTAL'!$C17*'1_TOTAL'!$D17 -> 42696 | F17: BANKING | G17: ='1_TOTAL'!$E17*100/'1_TOTAL'!$E$82 -> 1.4656821 | I17: MACHINARIES | J17: =SUM(G63:G64) -> 1.8971891 | K17: =SUM(E63:E64) -> 55266
A18: 1 | B18: Aklyl Amines | C18: 2378 | D18: 18 | E18: =D18*C18 -> 42804 | F18: CHEMICAL | G18: ='1_TOTAL'!$E18*100/'1_TOTAL'!$E$82 -> 1.4693895 | I18: NIFTY | J18: =G65 -> 0.027908927 | K18: =E65 -> 813
A19: 5 | B19: Clean Sciences | C19: 1535 | D19: 45 | E19: =D19*C19 -> 69075 | F19: CHEMICAL | G19: ='1_TOTAL'!$E19*100/'1_TOTAL'!$E$82 -> 2.3712289 | I19: PACKAGING | J19: =SUM(G66:G67) -> 2.7849659 | K19: =SUM(E66:E67) -> 81127.35
A20: 6 | B20: Galaxy Surfants | C20: 2793 | D20: 9 | E20: =D20*C20 -> 25137 | F20: CHEMICAL | G20: ='1_TOTAL'!$E20*100/'1_TOTAL'!$E$82 -> 0.86291106 | I20: PHARMA | J20: =SUM(G68:G69) -> 1.8005892 | K20: =SUM(E68:E69) -> 52452
A21: 20 | B21: Tatva Chintan Pharma | C21: 1525 | D21: 50 | E21: =D21*C21 -> 76250 | F21: CHEMICAL | G21: ='1_TOTAL'!$E21*100/'1_TOTAL'!$E$82 -> 2.6175346 | I21: PRINTING | J21: =G70 -> 0.88646029 | K21: =E70 -> 25823
A22: 60 | B22: AMIORG | C22: 1126 | D22: 6 | E22: ='1_TOTAL'!$C22*'1_TOTAL'!$D22 -> 6756 | F22: CHEMICAL | G22: ='1_TOTAL'!$E22*100/'1_TOTAL'!$E$82 -> 0.23192215 | I22: RENEWABLES | J22: =G71 -> 0.4462682 | K22: =E71 -> 13000
A23: 61 | B23: BALAJI AMINES | C23: 2220 | D23: 4 | E23: ='1_TOTAL'!$C23*'1_TOTAL'!$D23 -> 8880 | F23: CHEMICAL | G23: ='1_TOTAL'!$E23*100/'1_TOTAL'!$E$82 -> 0.30483551 | I23: RETAILS | J23: =SUM(G72:G81) -> 12.10646 | K23: =SUM(E72:E81) -> 352666.8
A24: 36 | B24: PRAJ | C24: 544 | D24: 30 | E24: ='1_TOTAL'!$C24*'1_TOTAL'!$D24 -> 16320 | F24: CLEAN ENERGY | G24: ='1_TOTAL'!$E24*100/'1_TOTAL'!$E$82 -> 0.56023823
A25: 27 | B25: KNR Construction | C25: 338.9 | D25: 30 | E25: ='1_TOTAL'!$C25*'1_TOTAL'!$D25 -> 10167 | F25: CONSTRUCTION | G25: ='1_TOTAL'!$E25*100/'1_TOTAL'!$E$82 -> 0.34901606
A26: 50 | B26: AHULIA CONST | C26: 1316.22 | D26: 20 | E26: ='1_TOTAL'!$C26*'1_TOTAL'!$D26 -> 26324.4 | F26: CONSTRUCTION | G26: ='1_TOTAL'!$E26*100/'1_TOTAL'!$E$82 -> 0.90367251 | I26: TOTAL | J26: =SUM(J2:J23) -> 100 | K26: =SUM(K2:K23) -> 2913046.5
A27: 73 | B27: L&T | C27: 3627 | D27: 15 | E27: ='1_TOTAL'!$C27*'1_TOTAL'!$D27 -> 54405 | F27: CONSTRUCTION | G27: ='1_TOTAL'!$E27*100/'1_TOTAL'!$E$82 -> 1.8676324
A28: 43 | B28: MTAR TECH | C28: 1734 | D28: 20 | E28: ='1_TOTAL'!$C28*'1_TOTAL'!$D28 -> 34680 | F28: DEFENCE | G28: ='1_TOTAL'!$E28*100/'1_TOTAL'!$E$82 -> 1.1905062
A29: 40 | B29: CROMPTON | C29: 80 | D29: 281 | E29: ='1_TOTAL'!$C29*'1_TOTAL'!$D29 -> 22480 | F29: ELECTRONICS | G29: ='1_TOTAL'!$E29*100/'1_TOTAL'!$E$82 -> 0.7717007
A30: 54 | B30: IKIO LIGHT | C30: 283 | D30: 70 | E30: ='1_TOTAL'!$C30*'1_TOTAL'!$D30 -> 19810 | F30: ELECTRONICS | G30: ='1_TOTAL'!$E30*100/'1_TOTAL'!$E$82 -> 0.68004408
A31: 58 | B31: IDEA FORGE | C31: 704 | D31: 22 | E31: ='1_TOTAL'!$C31*'1_TOTAL'!$D31 -> 15488 | F31: ELECTRONICS | G31: ='1_TOTAL'!$E31*100/'1_TOTAL'!$E$82 -> 0.53167707
A32: 59 | B32: PDSL | C32: 438 | D32: 52 | E32: ='1_TOTAL'!$C32*'1_TOTAL'!$D32 -> 22776 | F32: FASHION | G32: ='1_TOTAL'!$E32*100/'1_TOTAL'!$E$82 -> 0.78186189
A33: 14 | B33: JIO Finance | C33: 240.33 | D33: 225 | E33: =D33*C33 -> 54074.25 | F33: FINANCE | G33: ='1_TOTAL'!$E33*100/'1_TOTAL'!$E$82 -> 1.8562783
A34: 19 | B34: SBI Cards | C34: 728 | D34: 91 | E34: =D34*C34 -> 66248 | F34: FINANCE | G34: ='1_TOTAL'!$E34*100/'1_TOTAL'!$E$82 -> 2.2741827
A35: 25 | B35: UJJIVAN | C35: 41.82 | D35: 250 | E35: ='1_TOTAL'!$C35*'1_TOTAL'!$D35 -> 10455 | F35: FINANCE | G35: ='1_TOTAL'!$E35*100/'1_TOTAL'!$E$82 -> 0.35890262
A36: 26 | B36: JM Financils | C36: 93.48 | D36: 164 | E36: ='1_TOTAL'!$C36*'1_TOTAL'!$D36 -> 15330.72 | F36: FINANCE | G36: ='1_TOTAL'!$E36*100/'1_TOTAL'!$E$82 -> 0.52627791
A37: 30 | B37: MASFIN | C37: 278.93 | D37: 40 | E37: ='1_TOTAL'!$C37*'1_TOTAL'!$D37 -> 11157.2 | F37: FINANCE | G37: ='1_TOTAL'!$E37*100/'1_TOTAL'!$E$82 -> 0.38300797
A38: 35 | B38: AVAS | C38: 1543 | D38: 20 | E38: ='1_TOTAL'!$C38*'1_TOTAL'!$D38 -> 30860 | F38: FINANCE | G38: ='1_TOTAL'!$E38*100/'1_TOTAL'!$E$82 -> 1.059372
A39: 37 | B39: EQUITAS | C39: 206 | D39: 86.29 | E39: ='1_TOTAL'!$C39*'1_TOTAL'!$D39 -> 17775.74 | F39: FINANCE | G39: ='1_TOTAL'!$E39*100/'1_TOTAL'!$E$82 -> 0.61021135
A40: 57 | B40: CREDIT ACCESS | C40: 1233 | D40: 15 | E40: ='1_TOTAL'!$C40*'1_TOTAL'!$D40 -> 18495 | F40: FINANCE | G40: ='1_TOTAL'!$E40*100/'1_TOTAL'!$E$82 -> 0.63490234
...

Sheet 2_SECTOR WISE
A1: Sr.No | B1: Name of Script | C1: Stock Price | D1: Quantity | E1: Total | F1: SECTOR | G1: Total % | I1: Sector | J1: Sector % | K1: Total
A2: 23 | B2: UPL | C2: 505 | D2: 70 | E2: =D2*C2 -> 35350 | F2: AGRI | G2: ='2_SECTOR WISE'!$E2*100/'2_SECTOR WISE'!$E$82 -> 1.2135062 | I2: AGRI | J2: =SUM(G2:G3) -> 1.7689385 | K2: =SUM(E2:E3) -> 51530
A3: 52 | B3: GODJREJ AGROVET | C3: 809 | D3: 20 | E3: ='2_SECTOR WISE'!$C3*'2_SECTOR WISE'!$D3 -> 16180 | F3: AGRI | G3: ='2_SECTOR WISE'!$E3*100/'2_SECTOR WISE'!$E$82 -> 0.55543227 | I3: Auto Ancillaries | J3: =SUM(G4:G9) -> 4.7355922 | K3: =SUM(E4:E9) -> 137950
A4: 51 | B4: PCBL | C4: 748 | D4: 55 | E4: ='2_SECTOR WISE'!$C4*'2_SECTOR WISE'!$D4 -> 41140 | F4: AUTO ANCILLLARY | G4: ='2_SECTOR WISE'!$E4*100/'2_SECTOR WISE'!$E$82 -> 1.4122672 | I4: Aviation | J4: =G10 -> 0.78302905 | K4: =E10 -> 22810
A5: 44 | B5: SUPRAJIT | C5: 400 | D5: 100 | E5: ='2_SECTOR WISE'!$C5*'2_SECTOR WISE'!$D5 -> 40000 | F5: AUTO ANCILLLARY | G5: ='2_SECTOR WISE'!$E5*100/'2_SECTOR WISE'!$E$82 -> 1.3731329 | I5: Banking | J5: =SUM(G11:G17) -> 14.920188 | K5: =SUM(E11:E17) -> 434632
A6: 38 | B6: SANSERA | C6: 1033 | D6: 20 | E6: ='2_SECTOR WISE'!$C6*'2_SECTOR WISE'!$D6 -> 20660 | F6: AUTO ANCILLLARY | G6: ='2_SECTOR WISE'!$E6*100/'2_SECTOR WISE'!$E$82 -> 0.70922315 | I6: Chemical | J6: =SUM(G18:G23) -> 7.8578218 | K6: =SUM(E18:E23) -> 228902
A7: 53 | B7: VARROC | C7: 25 | D7: 548 | E7: ='2_SECTOR WISE'!$C7*'2_SECTOR WISE'!$D7 -> 13700 | F7: AUTO ANCILLLARY | G7: ='2_SECTOR WISE'!$E7*100/'2_SECTOR WISE'!$E$82 -> 0.47029803 | I7: CLEAN ENERGY | J7: =G24 -> 0.56023823 | K7: =E24 -> 16320
A8: 77 | B8: SHANTI GEARS | C8: 570 | D8: 21 | E8: ='2_SECTOR WISE'!$C8*'2_SECTOR WISE'!$D8 -> 11970 | F8: AUTO ANCILLLARY | G8: ='2_SECTOR WISE'!$E8*100/'2_SECTOR WISE'!$E$82 -> 0.41091003 | I8: CONSTRUCTION | J8: =SUM(G25:G27) -> 3.120321 | K8: =SUM(E25:E27) -> 90896.4
A9: 29 | B9: Pricol | C9: 524 | D9: 20 | E9: ='2_SECTOR WISE'!$C9*'2_SECTOR WISE'!$D9 -> 10480 | F9: AUTO ANCILLLARY | G9: ='2_SECTOR WISE'!$E9*100/'2_SECTOR WISE'!$E$82 -> 0.35976083 | I9: DEFENCE | J9: =G28 -> 1.1905062 | K9: =E28 -> 34680
A10: 78 | B10: INDIGO | C10: 4562 | D10: 5 | E10: ='2_SECTOR WISE'!$C10*'2_SECTOR WISE'!$D10 -> 22810 | F10: AVIATION | G10: ='2_SECTOR WISE'!$E10*100/'2_SECTOR WISE'!$E$82 -> 0.78302905 | I10: ELECTRONICS | J10: =SUM(G29:G31) -> 1.9834219 | K10: =SUM(E29:E31) -> 57778
A11: 8 | B11: HDFC Bank | C11: 1518.9 | D11: 100 | E11: =D11*C11 -> 151890 | F11: BANKING | G11: ='2_SECTOR WISE'!$E11*100/'2_SECTOR WISE'!$E$82 -> 5.214129 | I11: FASHION | J11: =G32 -> 0.78186189 | K11: =E32 -> 22776
A12: 15 | B12: Kotak Bank | C12: 1752 | D12: 71 | E12: =D12*C12 -> 124392 | F12: BANKING | G12: ='2_SECTOR WISE'!$E12*100/'2_SECTOR WISE'!$E$82 -> 4.2701688 | I12: FINANCE | J12: =SUM(G33:G41) -> 9.3289933 | K12: =SUM(E33:E41) -> 271757.91
A13: 11 | B13: IDFC First bank | C13: 81.17 | D13: 700 | E13: =D13*C13 -> 56819 | F13: BANKING | G13: ='2_SECTOR WISE'!$E13*100/'2_SECTOR WISE'!$E$82 -> 1.950501 | I13: FMCG | J13: =SUM(G42:G44) -> 10.041807 | K13: =SUM(E42:E44) -> 292522.5
A14: 67 | B14: ICICI BANK | C14: 1186 | D14: 36 | E14: ='2_SECTOR WISE'!$C14*'2_SECTOR WISE'!$D14 -> 42696 | F14: BANKING | G14: ='2_SECTOR WISE'!$E14*100/'2_SECTOR WISE'!$E$82 -> 1.4656821 | I14: INSURANCE | J14: =SUM(G45:G46) -> 3.0823745 | K14: =SUM(E45:E46) -> 89791
A15: 66 | B15: AXIS BANK | C15: 1175 | D15: 27 | E15: ='2_SECTOR WISE'!$C15*'2_SECTOR WISE'!$D15 -> 31725 | F15: BANKING | G15: ='2_SECTOR WISE'!$E15*100/'2_SECTOR WISE'!$E$82 -> 1.089066 | I15: IT | J15: =SUM(G47:G60) -> 17.91947 | K15: =SUM(E47:E60) -> 522002.5
A16: 55 | B16: RBL BANK | C16: 230 | D16: 100 | E16: ='2_SECTOR WISE'!$C16*'2_SECTOR WISE'!$D16 -> 23000 | F16: BANKING | G16: ='2_SECTOR WISE'!$E16*100/'2_SECTOR WISE'!$E$82 -> 0.78955143 | I16: LOGISTICS | J16: =SUM(G61:G62) -> 1.975595 | K16: =SUM(E61:E62) -> 57550
A17: 64 | B17: CITY BANK | C17: 137 | D17: 30 | E17: ='2_SECTOR WISE'!$C17*'2_SECTOR WISE'!$D17 -> 4110 | F17: BANKING | G17: ='2_SECTOR WISE'!$E17*100/'2_SECTOR WISE'!$E$82 -> 0.14108941 | I17: MACHINARIES | J17: =SUM(G63:G64) -> 1.8971891 | K17: =SUM(E63:E64) -> 55266
A18: 20 | B18: Tatva Chintan Pharma | C18: 1525 | D18: 50 | E18: =D18*C18 -> 76250 | F18: CHEMICAL | G18: ='2_SECTOR WISE'!$E18*100/'2_SECTOR WISE'!$E$82 -> 2.6175346 | I18: NIFTY | J18: =G65 -> 0.027908927 | K18: =E65 -> 813
A19: 5 | B19: Clean Sciences | C19: 1535 | D19: 45 | E19: =D19*C19 -> 69075 | F19: CHEMICAL | G19: ='2_SECTOR WISE'!$E19*100/'2_SECTOR WISE'!$E$82 -> 2.3712289 | I19: PACKAGING | J19: =SUM(G66:G67) -> 2.7849659 | K19: =SUM(E66:E67) -> 81127.35
A20: 1 | B20: Aklyl Amines | C20: 2378 | D20: 18 | E20: =D20*C20 -> 42804 | F20: CHEMICAL | G20: ='2_SECTOR WISE'!$E20*100/'2_SECTOR WISE'!$E$82 -> 1.4693895 | I20: PHARMA | J20: =SUM(G68:G69) -> 1.8005892 | K20: =SUM(E68:E69) -> 52452
A21: 6 | B21: Galaxy Surfants | C21: 2793 | D21: 9 | E21: =D21*C21 -> 25137 | F21: CHEMICAL | G21: ='2_SECTOR WISE'!$E21*100/'2_SECTOR WISE'!$E$82 -> 0.86291106 | I21: PRINTING | J21: =G70 -> 0.88646029 | K21: =E70 -> 25823
A22: 61 | B22: BALAJI AMINES | C22: 2220 | D22: 4 | E22: ='2_SECTOR WISE'!$C22*'2_SECTOR WISE'!$D22 -> 8880 | F22: CHEMICAL | G22: ='2_SECTOR WISE'!$E22*100/'2_SECTOR WISE'!$E$82 -> 0.30483551 | I22: RENEWABLES | J22: =G71 -> 0.4462682 | K22: =E71 -> 13000
A23: 60 | B23: AMIORG | C23: 1126 | D23: 6 | E23: ='2_SECTOR WISE'!$C23*'2_SECTOR WISE'!$D23 -> 6756 | F23: CHEMICAL | G23: ='2_SECTOR WISE'!$E23*100/'2_SECTOR WISE'!$E$82 -> 0.23192215 | I23: RETAILS | J23: =SUM(G72:G81) -> 12.10646 | K23: =SUM(E72:E81) -> 352666.8
A24: 36 | B24: PRAJ | C24: 544 | D24: 30 | E24: ='2_SECTOR WISE'!$C24*'2_SECTOR WISE'!$D24 -> 16320 | F24: CLEAN ENERGY | G24: ='2_SECTOR WISE'!$E24*100/'2_SECTOR WISE'!$E$82 -> 0.56023823
A25: 73 | B25: L&T | C25: 3627 | D25: 15 | E25: ='2_SECTOR WISE'!$C25*'2_SECTOR WISE'!$D25 -> 54405 | F25: CONSTRUCTION | G25: ='2_SECTOR WISE'!$E25*100/'2_SECTOR WISE'!$E$82 -> 1.8676324
A26: 50 | B26: AHULIA CONST | C26: 1316.22 | D26: 20 | E26: ='2_SECTOR WISE'!$C26*'2_SECTOR WISE'!$D26 -> 26324.4 | F26: CONSTRUCTION | G26: ='2_SECTOR WISE'!$E26*100/'2_SECTOR WISE'!$E$82 -> 0.90367251 | I26: TOTAL | J26: =SUM(J2:J23) -> 100 | K26: =SUM(K2:K23) -> 2913046.5
A27: 27 | B27: KNR Construction | C27: 338.9 | D27: 30 | E27: ='2_SECTOR WISE'!$C27*'2_SECTOR WISE'!$D27 -> 10167 | F27: CONSTRUCTION | G27: ='2_SECTOR WISE'!$E27*100/'2_SECTOR WISE'!$E$82 -> 0.34901606
A28: 43 | B28: MTAR TECH | C28: 1734 | D28: 20 | E28: ='2_SECTOR WISE'!$C28*'2_SECTOR WISE'!$D28 -> 34680 | F28: DEFENCE | G28: ='2_SECTOR WISE'!$E28*100/'2_SECTOR WISE'!$E$82 -> 1.1905062
A29: 40 | B29: CROMPTON | C29: 80 | D29: 281 | E29: ='2_SECTOR WISE'!$C29*'2_SECTOR WISE'!$D29 -> 22480 | F29: ELECTRONICS | G29: ='2_SECTOR WISE'!$E29*100/'2_SECTOR WISE'!$E$82 -> 0.7717007
A30: 54 | B30: IKIO LIGHT | C30: 283 | D30: 70 | E30: ='2_SECTOR WISE'!$C30*'2_SECTOR WISE'!$D30 -> 19810 | F30: ELECTRONICS | G30: ='2_SECTOR WISE'!$E30*100/'2_SECTOR WISE'!$E$82 -> 0.68004408
A31: 58 | B31: IDEA FORGE | C31: 704 | D31: 22 | E31: ='2_SECTOR WISE'!$C31*'2_SECTOR WISE'!$D31 -> 15488 | F31: ELECTRONICS | G31: ='2_SECTOR WISE'!$E31*100/'2_SECTOR WISE'!$E$82 -> 0.53167707
A32: 59 | B32: PDSL | C32: 438 | D32: 52 | E32: ='2_SECTOR WISE'!$C32*'2_SECTOR WISE'!$D32 -> 22776 | F32: FASHION | G32: ='2_SECTOR WISE'!$E32*100/'2_SECTOR WISE'!$E$82 -> 0.78186189
A33: 19 | B33: SBI Cards | C33: 728 | D33: 91 | E33: =D33*C33 -> 66248 | F33: FINANCE | G33: ='2_SECTOR WISE'!$E33*100/'2_SECTOR WISE'!$E$82 -> 2.2741827
A34: 14 | B34: JIO Finance | C34: 240.33 | D34: 225 | E34: =D34*C34 -> 54074.25 | F34: FINANCE | G34: ='2_SECTOR WISE'!$E34*100/'2_SECTOR WISE'!$E$82 -> 1.8562783
A35: 72 | B35: BAJAJ FINANCE | C35: 6766 | D35: 7 | E35: ='2_SECTOR WISE'!$C35*'2_SECTOR WISE'!$D35 -> 47362 | F35: FINANCE | G35: ='2_SECTOR WISE'!$E35*100/'2_SECTOR WISE'!$E$82 -> 1.625858
A36: 35 | B36: AVAS | C36: 1543 | D36: 20 | E36: ='2_SECTOR WISE'!$C36*'2_SECTOR WISE'!$D36 -> 30860 | F36: FINANCE | G36: ='2_SECTOR WISE'!$E36*100/'2_SECTOR WISE'!$E$82 -> 1.059372
A37: 57 | B37: CREDIT ACCESS | C37: 1233 | D37: 15 | E37: ='2_SECTOR WISE'!$C37*'2_SECTOR WISE'!$D37 -> 18495 | F37: FINANCE | G37: ='2_SECTOR WISE'!$E37*100/'2_SECTOR WISE'!$E$82 -> 0.63490234
A38: 37 | B38: EQUITAS | C38: 206 | D38: 86.29 | E38: ='2_SECTOR WISE'!$C38*'2_SECTOR WISE'!$D38 -> 17775.74 | F38: FINANCE | G38: ='2_SECTOR WISE'!$E38*100/'2_SECTOR WISE'!$E$82 -> 0.61021135
A39: 26 | B39: JM Financils | C39: 93.48 | D39: 164 | E39: ='2_SECTOR WISE'!$C39*'2_SECTOR WISE'!$D39 -> 15330.72 | F39: FINANCE | G39: ='2_SECTOR WISE'!$E39*100/'2_SECTOR WISE'!$E$82 -> 0.52627791
A40: 30 | B40: MASFIN | C40: 278.93 | D40: 40 | E40: ='2_SECTOR WISE'!$C40*'2_SECTOR WISE'!$D40 -> 11157.2 | F40: FINANCE | G40: ='2_SECTOR WISE'!$E40*100/'2_SECTOR WISE'!$E$82 -> 0.38300797
...
